<?xml version="1.0"?>
<robot name="tricycle_drive" xmlns:xacro="http://ros.org/wiki/xacro">
  <material name="IPA/LightGrey">
    <color rgba="0.7 0.7 0.7 1.0"/>
  </material>
  <material name="IPA/DarkGrey">
    <color rgba="0.4 0.4 0.4 1.0"/>
  </material>
  <material name="IPA/Black">
    <color rgba="0.0 0.0 0.0 1.0"/>
  </material>
  <material name="IPA/Metall">
    <color rgba="0.7 0.7 0.7 1.0"/>
  </material>
  <material name="IPA/YellowRubber">
    <color rgba="0.4 0.27 0.16 1.0"/>
  </material>
  <material name="IPA/Orange">
    <color rgba="1.0 0.4 0.0 1.0"/>
  </material>
  <material name="IPA/Blue">
    <color rgba="0.0 0.0 0.5 1.0"/>
  </material>
  <material name="Black">
    <color rgba="0 0 0 1" />
  </material>
  <material name="Grey">
    <color rgba="0.8 0.8 0.8 1" />
  </material>
  <material name="Orange">
    <color rgba="1 0.6 0 1" />
  </material>
  <material name="White">
    <color rgba="1 1 1 1" />
  </material>
  <!-- base_link -->
  <link name="base_link" />
  <!-- base_footprint -->
  <link name="base_footprint"/>
  <joint name="base_footprint_joint" type="fixed">
    <parent link="base_link"/>
    <child link="base_footprint"/>
    <origin xyz="0 0 0" rpy="0 0 0"/>
  </joint>
  
  <joint name="base_charger_joint" type="fixed">
    <origin rpy="0 0 0" xyz="0.2992 0.0 0.09089"/>
    <parent link="base_chassis_link"/>
    <child link="base_charger_link"/>
  </joint>
  <!-- base_charger -->
  <link name="base_charger_link"/>
  <!-- Chassis -->
  <link name="base_chassis_link">
    <inertial>
      <origin xyz="0 0 0"/>
      <mass value="10"/>
      <inertia ixx="5.652232699207" ixy="-0.009719934438" ixz="1.293988226423" iyy="5.669473158652" iyz="-0.007379583694" izz="3.683196351726"/>
    </inertial>
    <visual>
      <origin rpy="0 0 1.0472" xyz="0 0 0"/>
      <geometry>
        <!-- <mesh filename="package://cob_description/meshes/cob4_base/base.dae"/> -->
        <mesh filename="file://$(find tricycle_sim)/meshes/cob4_base/base.dae"/>
        <!--box size="0.01 0.01 0.01" /-->
      </geometry>
    </visual>
    <collision>
      <origin rpy="0 0 1.0472" xyz="0 0 0"/>
      <geometry>
        <mesh filename="file://$(find tricycle_sim)/meshes/cob4_base/base_collision.stl"/>
        <!--box size="0.01 0.01 0.01" /-->
      </geometry>
    </collision>
  </link>

  <joint name="base_chassis_joint" type="fixed">
    <origin rpy="0 0 0" xyz="0 0 0"/>
    <parent link="base_link"/>
    <child link="base_chassis_link"/>
  </joint>

  <!-- left wheel rotation link  -->
  <joint name="fl_caster_rotation_joint" type="fixed">
    <origin rpy="0 0 0" xyz="-0.12422 0.21515 0.0782"/>
    <parent link="base_chassis_link"/>
    <child link="fl_caster_rotation_link"/>
  </joint>
  <link name="fl_caster_rotation_link">
    <inertial>
      <origin xyz="0 0 0"/>
      <mass value="5.9"/>
      <inertia ixx="0.04" ixy="-0.0007" ixz="0.0" iyy="0.02" iyz="-0.000004" izz="0.05"/>
    </inertial>
    <visual>
      <geometry>
        <mesh filename="file://$(find tricycle_sim)/meshes/drive_wheel/caster.stl"/>
      </geometry>
      <material name="IPA/LightGrey"/>
    </visual>
    <collision>
      <geometry>
        <box size="0.001 0.001 0.001"/>
      </geometry>
    </collision>
  </link>
  <!-- left wheel Link -->
  <link name="fl_caster_r_wheel_link">
    <collision>
      <geometry>
        <cylinder length="0.005" radius="0.0782" />
      </geometry>
    </collision>
    <visual>
      <geometry>
        <!-- <cylinder length="0.08" radius="0.0782" /> -->
        <mesh filename="file://$(find tricycle_sim)/meshes/drive_wheel/wheel.dae"/>
      </geometry>
      <origin rpy="-1.5708 0 0"/>
      <material name="Black" />
    </visual>
    <inertial>
      <origin xyz="0 0 0"/>
      <mass value="0.44036"/>
      <inertia ixx="0.012411765597" ixy="-0.000711733678" ixz="0.00050272983" iyy="0.015218160428" iyz="-0.000004273467" izz="0.011763977943"/>
    </inertial>
  </link>

  <joint name="fl_caster_r_wheel_joint" type="continuous">
    <origin xyz="-0.12422 0.21515 0.0782" rpy="-1.57 0 0" />
    <parent link="base_chassis_link" />
    <child link="fl_caster_r_wheel_link" />
    <axis xyz="0 0 1" />
    <dynamics damping="0.2" />
  </joint>

  <!-- right wheel rotation link -->
  <joint name="fr_caster_rotation_joint" type="fixed">
    <origin rpy="0 0 0" xyz="-0.12422 -0.21515 0.0782"/>
    <parent link="base_chassis_link"/>
    <child link="fr_caster_rotation_link"/>
  </joint>
  <link name="fr_caster_rotation_link">
    <inertial>
      <origin xyz="0 0 0"/>
      <mass value="5.9"/>
      <inertia ixx="0.04" ixy="-0.0007" ixz="0.0" iyy="0.02" iyz="-0.000004" izz="0.05"/>
    </inertial>
    <visual>
      <geometry>
        <mesh filename="file://$(find tricycle_sim)/meshes/drive_wheel/caster.stl"/>
      </geometry>
      <material name="IPA/LightGrey"/>
    </visual>
    <collision>
      <geometry>
        <box size="0.001 0.001 0.001"/>
      </geometry>
    </collision>
  </link>

  <!-- right wheel Link -->
  <link name="fr_caster_r_wheel_link">
    <collision>
      <geometry>
        <cylinder length="0.005" radius="0.0782" />
      </geometry>
    </collision>
    <visual>
      <geometry>
        <!-- <cylinder length="0.08" radius="0.0782" /> -->
        <mesh filename="file://$(find tricycle_sim)/meshes/drive_wheel/wheel.dae"/>
      </geometry>
      <origin rpy="-1.5708 0 0"/>
      <material name="Black" />
    </visual>
    <inertial>
      <origin xyz="0 0 0"/>
      <mass value="0.44036"/>
      <inertia ixx="0.012411765597" ixy="-0.000711733678" ixz="0.00050272983" iyy="0.015218160428" iyz="-0.000004273467" izz="0.011763977943"/>
    </inertial>
  </link>

  <joint name="fr_caster_r_wheel_joint" type="continuous">
    <origin xyz="-0.12422 -0.21515 0.0782" rpy="-1.57 0 0" />
    <parent link="base_chassis_link" />
    <child link="fr_caster_r_wheel_link" />
    <axis xyz="0 0 1" />
    <dynamics damping="0.2" />
  </joint>

  <!-- Steering Link -->
  <link name="b_caster_rotation_link">
    <inertial>
      <origin xyz="0 0 0"/>
      <mass value="5.9"/>
      <inertia ixx="0.04" ixy="-0.0007" ixz="0.0" iyy="0.02" iyz="-0.000004" izz="0.05"/>
    </inertial>
    <visual>
      <geometry>
        <mesh filename="file://$(find tricycle_sim)/meshes/drive_wheel/caster.stl"/>
      </geometry>
      <material name="IPA/LightGrey"/>
    </visual>
    <collision>
      <geometry>
        <box size="0.001 0.001 0.001"/>
      </geometry>
    </collision>
  </link>

  <joint name="b_caster_rotation_joint" type="continuous">
    <origin xyz="0.24844 0.0 0.0782" rpy="0 0 0" />
    <parent link="base_chassis_link" />
    <child link="b_caster_rotation_link" />
    <axis xyz="0 0 1" />
  </joint>

  <!-- front wheel link -->
  <link name="b_caster_r_wheel_link">
    <visual>
      <geometry>
        <!-- <cylinder length="0.08" radius="0.0782" /> -->
        <mesh filename="file://$(find tricycle_sim)/meshes/drive_wheel/wheel.dae"/>
      </geometry>
      <origin rpy="-1.5708 0 0"/>
      <material name="Black" />
    </visual>
    <inertial>
      <origin xyz="0 0 0"/>
      <mass value="5.9"/>
      <inertia ixx="0.04" ixy="-0.0007" ixz="0.0" iyy="0.02" iyz="-0.000004" izz="0.05"/>
    </inertial>
    <collision>
      <geometry>
        <cylinder length="0.005" radius="0.0782" />
      </geometry>
    </collision>
  </link>

  <joint name="b_caster_r_wheel_joint" type="continuous">
    <parent link="b_caster_rotation_link" />
    <child link="b_caster_r_wheel_link" />
    <origin xyz="0 0 0" rpy="-1.57 1.57 0" />
    <axis xyz="0 0 1" />
  </joint>

  <ros2_control name="GazeboSystem" type="system">
    <hardware>
      <plugin>gazebo_ros2_control/GazeboSystem</plugin>
    </hardware>
    <joint name="b_caster_rotation_joint">
      <command_interface name="position" />
      <state_interface name="position" />
    </joint>
    <joint name="b_caster_r_wheel_joint">
      <command_interface name="velocity" />
      <state_interface name="velocity" />
      <state_interface name="position" />
    </joint>
  </ros2_control>

  <!-- laser -->
  <joint name="base_laser_front_joint" type="fixed">
    <origin rpy="0.0 0.0 3.14" xyz="-0.244 0.0 0.20858"/>
    <parent link="base_link"/>
    <child link="base_laser_front_link"/>
  </joint>
  <link name="base_laser_front_link" type="laser">
    <inertial>
      <mass value="1.2"/>
      <origin rpy="0 0 0" xyz="0 0 0"/>
      <inertia ixx="0.0029999987999999997" ixy="0.0" ixz="0.0" iyy="0.0029999987999999997" iyz="0.0" izz="0.0015"/>
    </inertial>
    <visual>
      <origin rpy="0 0 0" xyz="0 0 0"/>
      <geometry>
        <mesh filename="file://$(find tricycle_sim)/meshes/sensors/sick_s300_laser.dae"/>

      </geometry>
      <material name="IPA/LightGrey"/>
    </visual>
    <collision>
      <origin rpy="0 0 0" xyz="0 0 0"/>
      <geometry>
        <mesh filename="file://$(find tricycle_sim)/meshes/sensors/sick_s300_laser_collision.stl"/>
      </geometry>
    </collision>
  </link>
  <gazebo reference="base_laser_front_link">
    <sensor name="base_laser_front" type="ray">
      <always_on>true</always_on>
      <update_rate>12.0</update_rate>
      <pose>0 0 0 0 0 0</pose>
      <visualize>true</visualize>
      <ray>
        <scan>
          <horizontal>
            <samples>541</samples>
            <resolution>1.0</resolution>
            <min_angle>-1.5708</min_angle>
            <max_angle>1.5708</max_angle>
          </horizontal>
        </scan>
        <range>
          <min>0.05</min>
          <max>29.5</max>
          <resolution>0.03</resolution>
        </range>
        <noise>
          <type>gaussian</type>
          <mean>0.0</mean>
          <stddev>0.02</stddev>
        </noise>
      </ray>
      <!-- <plugin filename="libgazebo_ros_laser.so" name="gazebo_ros_base_laser_front_controller">
        <topicName>base_laser_front/scan_raw</topicName>
        <frameName>base_laser_front_link</frameName>
      </plugin> -->
      <plugin name="gazebo_ros_base_laser_front_controller" filename="libgazebo_ros_ray_sensor.so">
        <ros>
          <namespace>base_laser_front</namespace>
          <remapping>~/out:=scan_raw</remapping>
        </ros>
        <output_type>sensor_msgs/LaserScan</output_type>
      </plugin>
    </sensor>
  </gazebo>
  <joint name="base_laser_left_joint" type="fixed">
    <origin rpy="0.0 0.0 1.0472" xyz="0.122 0.21131 0.20858"/>
    <parent link="base_link"/>
    <child link="base_laser_left_link"/>
  </joint>
  <link name="base_laser_left_link" type="laser">
    <inertial>
      <mass value="1.2"/>
      <origin rpy="0 0 0" xyz="0 0 0"/>
      <inertia ixx="0.0029999987999999997" ixy="0.0" ixz="0.0" iyy="0.0029999987999999997" iyz="0.0" izz="0.0015"/>
    </inertial>
    <visual>
      <origin rpy="0 0 0" xyz="0 0 0"/>
      <geometry>
        <mesh filename="file://$(find tricycle_sim)/meshes/sensors/sick_s300_laser.dae"/>

      </geometry>
      <material name="IPA/LightGrey"/>
    </visual>
    <collision>
      <origin rpy="0 0 0" xyz="0 0 0"/>
      <geometry>
        <mesh filename="file://$(find tricycle_sim)/meshes/sensors/sick_s300_laser_collision.stl"/>
      </geometry>
    </collision>
  </link>
  <gazebo reference="base_laser_left_link">
    <sensor name="base_laser_left" type="ray">
      <always_on>true</always_on>
      <update_rate>12.0</update_rate>
      <pose>0 0 0 0 0 0</pose>
      <visualize>true</visualize>
      <ray>
        <scan>
          <horizontal>
            <samples>541</samples>
            <resolution>1.0</resolution>
            <min_angle>-1.5708</min_angle>
            <max_angle>1.5708</max_angle>
          </horizontal>
        </scan>
        <range>
          <min>0.05</min>
          <max>29.5</max>
          <resolution>0.03</resolution>
        </range>
        <noise>
          <type>gaussian</type>
          <mean>0.0</mean>
          <stddev>0.02</stddev>
        </noise>
      </ray>
      <!-- <plugin filename="libgazebo_ros_laser.so" name="gazebo_ros_base_laser_left_controller">
        <topicName>base_laser_left/scan_raw</topicName>
        <frameName>base_laser_left_link</frameName>
      </plugin> -->
      <plugin name="gazebo_ros_base_laser_left_controller" filename="libgazebo_ros_ray_sensor.so">
        <ros>
          <namespace>base_laser_left</namespace>
          <remapping>~/out:=scan_raw</remapping>
        </ros>
        <output_type>sensor_msgs/LaserScan</output_type>
      </plugin>
    </sensor>
  </gazebo>
  <joint name="base_laser_right_joint" type="fixed">
    <origin rpy="0.0 0.0 -1.0472" xyz="0.122 -0.21131 0.20858"/>
    <parent link="base_link"/>
    <child link="base_laser_right_link"/>
  </joint>
  <link name="base_laser_right_link" type="laser">
    <inertial>
      <mass value="1.2"/>
      <origin rpy="0 0 0" xyz="0 0 0"/>
      <inertia ixx="0.0029999987999999997" ixy="0.0" ixz="0.0" iyy="0.0029999987999999997" iyz="0.0" izz="0.0015"/>
    </inertial>
    <visual>
      <origin rpy="0 0 0" xyz="0 0 0"/>
      <geometry>
        <mesh filename="file://$(find tricycle_sim)/meshes/sensors/sick_s300_laser.dae"/>
      </geometry>
      <material name="IPA/LightGrey"/>
    </visual>
    <collision>
      <origin rpy="0 0 0" xyz="0 0 0"/>
      <geometry>
        <mesh filename="file://$(find tricycle_sim)/meshes/sensors/sick_s300_laser_collision.stl"/>
      </geometry>
    </collision>
  </link>
  <gazebo reference="base_laser_right_link">
    <sensor name="base_laser_right" type="ray">
      <always_on>true</always_on>
      <update_rate>12.0</update_rate>
      <pose>0 0 0 0 0 0</pose>
      <visualize>true</visualize>
      <ray>
        <scan>
          <horizontal>
            <samples>541</samples>
            <resolution>1.0</resolution>
            <min_angle>-1.5708</min_angle>
            <max_angle>1.5708</max_angle>
          </horizontal>
        </scan>
        <range>
          <min>0.05</min>
          <max>29.5</max>
          <resolution>0.03</resolution>
        </range>
        <noise>
          <type>gaussian</type>
          <mean>0.0</mean>
          <stddev>0.02</stddev>
        </noise>
      </ray>
      <!-- <plugin filename="libgazebo_ros_laser.so" name="gazebo_ros_base_laser_right_controller">
        <topicName>base_laser_right/scan_raw</topicName>
        <frameName>base_laser_right_link</frameName>
      </plugin> -->
      <plugin name="gazebo_ros_base_laser_right_controller" filename="libgazebo_ros_ray_sensor.so">
        <ros>
          <namespace>base_laser_right</namespace>
          <remapping>~/out:=scan_raw</remapping>
        </ros>
        <output_type>sensor_msgs/LaserScan</output_type>
      </plugin>
    </sensor>
  </gazebo>

  <!-- imu -->
  <link name="imu_link">
    <visual>
      <geometry>
        <box size="0.1 0.1 0.1"/>
      </geometry>
    </visual>

    <collision>
      <geometry>
        <box size="0.1 0.1 0.1"/>
      </geometry>
    </collision>
  </link>

  <joint name="imu_joint" type="fixed">
    <parent link="base_chassis_link"/>
    <child link="imu_link"/>
    <origin xyz="0 0 0.2"/>
  </joint>

  <gazebo reference="imu_link">
    <sensor name="imu_sensor" type="imu">
    <plugin filename="libgazebo_ros_imu_sensor.so" name="imu_plugin">
        <ros>
          <namespace>/demo</namespace>
          <remapping>~/out:=imu</remapping>
        </ros>
        <initial_orientation_as_reference>false</initial_orientation_as_reference>
      </plugin>
      <always_on>true</always_on>
      <update_rate>100</update_rate>
      <visualize>true</visualize>
      <imu>
        <angular_velocity>
          <x>
            <noise type="gaussian">
              <mean>0.0</mean>
              <stddev>2e-4</stddev>
              <bias_mean>0.0000075</bias_mean>
              <bias_stddev>0.0000008</bias_stddev>
            </noise>
          </x>
          <y>
            <noise type="gaussian">
              <mean>0.0</mean>
              <stddev>2e-4</stddev>
              <bias_mean>0.0000075</bias_mean>
              <bias_stddev>0.0000008</bias_stddev>
            </noise>
          </y>
          <z>
            <noise type="gaussian">
              <mean>0.0</mean>
              <stddev>2e-4</stddev>
              <bias_mean>0.0000075</bias_mean>
              <bias_stddev>0.0000008</bias_stddev>
            </noise>
          </z>
        </angular_velocity>
        <linear_acceleration>
          <x>
            <noise type="gaussian">
              <mean>0.0</mean>
              <stddev>1.7e-2</stddev>
              <bias_mean>0.1</bias_mean>
              <bias_stddev>0.001</bias_stddev>
            </noise>
          </x>
          <y>
            <noise type="gaussian">
              <mean>0.0</mean>
              <stddev>1.7e-2</stddev>
              <bias_mean>0.1</bias_mean>
              <bias_stddev>0.001</bias_stddev>
            </noise>
          </y>
          <z>
            <noise type="gaussian">
              <mean>0.0</mean>
              <stddev>1.7e-2</stddev>
              <bias_mean>0.1</bias_mean>
              <bias_stddev>0.001</bias_stddev>
            </noise>
          </z>
        </linear_acceleration>
      </imu>
    </sensor>
  </gazebo> 

  <gazebo>
    <plugin filename="libgazebo_ros2_control.so" name="gazebo_ros2_control">
      <parameters>$(find tricycle_sim)/config/cob_tricycle_drive_controller.yaml</parameters>
    </plugin>
  </gazebo>

</robot>
