<?xml version="1.0" ?>
<!-- =================================================================================== -->
<!-- |    This document was autogenerated by xacro from cob4-25_torso.urdf.xacro       | -->
<!-- |    EDITING THIS FILE BY HAND IS NOT RECOMMENDED                                 | -->
<!-- =================================================================================== -->
<robot name="cob4-25">
  <material name="IPA/LightGrey">
    <color rgba="0.7 0.7 0.7 1.0"/>
  </material>
  <material name="IPA/DarkGrey">
    <color rgba="0.4 0.4 0.4 1.0"/>
  </material>
  <material name="IPA/Black">
    <color rgba="0.0 0.0 0.0 1.0"/>
  </material>
  <material name="IPA/Metall">
    <color rgba="0.7 0.7 0.7 1.0"/>
  </material>
  <material name="IPA/YellowRubber">
    <color rgba="0.4 0.27 0.16 1.0"/>
  </material>
  <material name="IPA/Orange">
    <color rgba="1.0 0.4 0.0 1.0"/>
  </material>
  <material name="IPA/Blue">
    <color rgba="0.0 0.0 0.5 1.0"/>
  </material>

  <!-- <link name="base_pivot_link"/>
  <joint name="base_pivot_joint" type="fixed">
    <origin rpy="0 0 0" xyz="-0.12422 0.0 0.0"/>
    <parent link="base_pivot_link"/>
    <child link="base_footprint"/>
  </joint> -->
  <link name="base_footprint"/>
  <joint name="base_footprint_joint" type="fixed">
    <origin rpy="0 0 0" xyz="0 0 0"/>
    <parent link="base_footprint"/>
    <child link="base_link"/>
  </joint>
  <link name="base_link"/>
  <joint name="base_chassis_joint" type="fixed">
    <origin rpy="0 0 0" xyz="0 0 0"/>
    <parent link="base_link"/>
    <child link="base_chassis_link"/>
  </joint>
  <link name="base_chassis_link">
    <inertial>
      <origin xyz="0 0 0"/>
      <!-- <mass value="100"/> -->
      <mass value="10"/>
      <inertia ixx="5.652232699207" ixy="-0.009719934438" ixz="1.293988226423" iyy="5.669473158652" iyz="-0.007379583694" izz="3.683196351726"/>
    </inertial>
    <visual>
      <origin rpy="0 0 0" xyz="0 0 0"/>
      <geometry>
        <!-- <mesh filename="file:///home/nhg-yc/ros2_ws/cob_ws/install/cob_description/share/cob_description/meshes/cob4_base/base.dae"/> -->
        <mesh filename="file:///home/nhg-yc/ros2_ws/cob_ws/install/cob_description/share/cob_description/meshes/cob4_base/base.dae"/>
        <!--box size="0.01 0.01 0.01" /-->
      </geometry>
    </visual>
    <collision>
      <origin rpy="0 0 0" xyz="0 0 0"/>
      <geometry>
        <mesh filename="file:///home/nhg-yc/ros2_ws/cob_ws/install/cob_description/share/cob_description/meshes/cob4_base/base_collision.stl"/>
        <!--box size="0.01 0.01 0.01" /-->
      </geometry>
    </collision>
  </link>
  <joint name="base_charger_joint" type="fixed">
    <origin rpy="0 0 0" xyz="0.2992 0.0 0.09089"/>
    <parent link="base_chassis_link"/>
    <child link="base_charger_link"/>
  </joint>
  <link name="base_charger_link"/>
  <joint name="fl_caster_rotation_joint" type="fixed">
    <origin rpy="0 0 0" xyz="0.12422 0.21515 0.0782"/>
    <parent link="base_chassis_link"/>
    <child link="fl_caster_rotation_link"/>
  </joint>
  <link name="fl_caster_rotation_link">
    <inertial>
      <origin xyz="0 0 0"/>
      <mass value="5.9"/>
      <inertia ixx="0.04" ixy="-0.0007" ixz="0.0" iyy="0.02" iyz="-0.000004" izz="0.05"/>
    </inertial>
    <visual>
      <geometry>
        <mesh filename="file:///home/nhg-yc/ros2_ws/cob_ws/install/cob_description/share/cob_description/meshes/drive_wheel/caster.stl"/>
      </geometry>
      <material name="IPA/LightGrey"/>
    </visual>
    <collision>
      <geometry>
        <box size="0.001 0.001 0.001"/>
      </geometry>
    </collision>
  </link>
  <joint name="fl_caster_r_wheel_joint" type="continuous">
    <origin rpy="0 0 0" xyz="0 -0.0 0"/>
    <parent link="fl_caster_rotation_link"/>
    <child link="fl_caster_r_wheel_link"/>
    <axis xyz="0 1 0"/>
    <!-- <safety_controller  k_velocity="10" />
        <limit effort="0.0" velocity="${drive_vel}"/>
        <dynamics damping="0.0" friction="0.0" /> -->
  </joint>
  <link name="fl_caster_r_wheel_link">
    <inertial>
      <origin xyz="0 0 0"/>
      <mass value="0.44036"/>
      <inertia ixx="0.012411765597" ixy="-0.000711733678" ixz="0.00050272983" iyy="0.015218160428" iyz="-0.000004273467" izz="0.011763977943"/>
    </inertial>
    <visual>
      <geometry>
        <mesh filename="file:///home/nhg-yc/ros2_ws/cob_ws/install/cob_description/share/cob_description/meshes/drive_wheel/wheel.dae"/>
      </geometry>
    </visual>
    <collision>
      <geometry>
        <mesh filename="file:///home/nhg-yc/ros2_ws/cob_ws/install/cob_description/share/cob_description/meshes/drive_wheel/wheel.stl"/>
      </geometry>
    </collision>
  </link>
  <gazebo reference="fl_caster_r_wheel_link">
    <gravity>true</gravity>
    <self_collide>false</self_collide>
  </gazebo>
  <gazebo reference="fl_caster_rotation_link">
    <gravity>true</gravity>
    <self_collide>false</self_collide>
    <material value="IPA/Metal"/>
  </gazebo>
  <joint name="b_caster_rotation_joint" type="continuous">
    <origin rpy="0 0 0" xyz="-0.24844 0.0 0.0782"/>
    <parent link="base_chassis_link"/>
    <child link="b_caster_rotation_link"/>
    <axis xyz="0 0 1"/>
    <!-- <safety_controller  k_velocity="10" />
        <limit effort="100" velocity="${steer_vel}"/>
        <dynamics damping="0.0" friction="0.0" /> -->
  </joint>
  <link name="b_caster_rotation_link">
    <inertial>
      <origin xyz="0 0 0"/>
      <mass value="5.9"/>
      <inertia ixx="0.04" ixy="-0.0007" ixz="0.0" iyy="0.02" iyz="-0.000004" izz="0.05"/>
    </inertial>
    <visual>
      <geometry>
        <mesh filename="file:///home/nhg-yc/ros2_ws/cob_ws/install/cob_description/share/cob_description/meshes/drive_wheel/caster.stl"/>
      </geometry>
      <material name="IPA/LightGrey"/>
    </visual>
    <collision>
      <geometry>
        <box size="0.001 0.001 0.001"/>
      </geometry>
    </collision>
  </link>
  <transmission name="b_caster_rotation_trans">
    <type>transmission_interface/SimpleTransmission</type>
    <joint name="b_caster_rotation_joint">
      <hardwareInterface>hardware_interface/PositionJointInterface</hardwareInterface>
      <hardwareInterface>hardware_interface/VelocityJointInterface</hardwareInterface>
    </joint>
    <actuator name="b_caster_rotation_motor">
      <mechanicalReduction>-79.23809523809524</mechanicalReduction>
    </actuator>
  </transmission>
  <joint name="b_caster_r_wheel_joint" type="continuous">
    <origin rpy="0 0 0" xyz="0 -0.0 0"/>
    <parent link="b_caster_rotation_link"/>
    <child link="b_caster_r_wheel_link"/>
    <axis xyz="0 1 0"/>
    <!-- <safety_controller  k_velocity="10" />
        <limit effort="100" velocity="${drive_vel}"/>
        <dynamics damping="0.0" friction="0.0" /> -->
  </joint>
  <link name="b_caster_r_wheel_link">
    <inertial>
      <origin xyz="0 0 0"/>
      <mass value="0.44036"/>
      <inertia ixx="0.012411765597" ixy="-0.000711733678" ixz="0.00050272983" iyy="0.015218160428" iyz="-0.000004273467" izz="0.011763977943"/>
    </inertial>
    <visual>
      <geometry>
        <mesh filename="file:///home/nhg-yc/ros2_ws/cob_ws/install/cob_description/share/cob_description/meshes/drive_wheel/wheel.dae"/>
      </geometry>
    </visual>
    <collision>
      <geometry>
        <mesh filename="file:///home/nhg-yc/ros2_ws/cob_ws/install/cob_description/share/cob_description/meshes/drive_wheel/wheel.stl"/>
      </geometry>
    </collision>
  </link>
  <gazebo reference="b_caster_r_wheel_link">
    <gravity>true</gravity>
    <self_collide>false</self_collide>
  </gazebo>
  <transmission name="b_caster_r_wheel_trans">
    <type>transmission_interface/SimpleTransmission</type>
    <joint name="b_caster_r_wheel_joint">
      <hardwareInterface>hardware_interface/VelocityJointInterface</hardwareInterface>
    </joint>
    <actuator name="b_caster_r_wheel_motor">
      <mechanicalReduction>-79.23809523809524</mechanicalReduction>
    </actuator>
  </transmission>
  <gazebo reference="b_caster_rotation_link">
    <gravity>true</gravity>
    <self_collide>false</self_collide>
    <material value="IPA/Metal"/>
  </gazebo>
  <joint name="fr_caster_rotation_joint" type="fixed">
    <origin rpy="0 0 0" xyz="0.12422 -0.21515 0.0782"/>
    <parent link="base_chassis_link"/>
    <child link="fr_caster_rotation_link"/>
  </joint>
  <link name="fr_caster_rotation_link">
    <inertial>
      <origin xyz="0 0 0"/>
      <mass value="5.9"/>
      <inertia ixx="0.04" ixy="-0.0007" ixz="0.0" iyy="0.02" iyz="-0.000004" izz="0.05"/>
    </inertial>
    <visual>
      <geometry>
        <mesh filename="file:///home/nhg-yc/ros2_ws/cob_ws/install/cob_description/share/cob_description/meshes/drive_wheel/caster.stl"/>
      </geometry>
      <material name="IPA/LightGrey"/>
    </visual>
    <collision>
      <geometry>
        <box size="0.001 0.001 0.001"/>
      </geometry>
    </collision>
  </link>
  <joint name="fr_caster_r_wheel_joint" type="continuous">
    <origin rpy="0 0 0" xyz="0 -0.0 0"/>
    <parent link="fr_caster_rotation_link"/>
    <child link="fr_caster_r_wheel_link"/>
    <axis xyz="0 1 0"/>
    <!-- <safety_controller  k_velocity="10" />
        <limit effort="0.0" velocity="${drive_vel}"/>
        <dynamics damping="0.0" friction="0.0" /> -->
  </joint>
  <link name="fr_caster_r_wheel_link">
    <inertial>
      <origin xyz="0 0 0"/>
      <mass value="0.44036"/>
      <inertia ixx="0.012411765597" ixy="-0.000711733678" ixz="0.00050272983" iyy="0.015218160428" iyz="-0.000004273467" izz="0.011763977943"/>
    </inertial>
    <visual>
      <geometry>
        <mesh filename="file:///home/nhg-yc/ros2_ws/cob_ws/install/cob_description/share/cob_description/meshes/drive_wheel/wheel.dae"/>
      </geometry>
    </visual>
    <collision>
      <geometry>
        <mesh filename="file:///home/nhg-yc/ros2_ws/cob_ws/install/cob_description/share/cob_description/meshes/drive_wheel/wheel.stl"/>
      </geometry>
    </collision>
  </link>
  <gazebo reference="fr_caster_r_wheel_link">
    <gravity>true</gravity>
    <self_collide>false</self_collide>
  </gazebo>
  <gazebo reference="fr_caster_rotation_link">
    <gravity>true</gravity>
    <self_collide>false</self_collide>
    <material value="IPA/Metal"/>
  </gazebo>

  <joint name="base_laser_front_joint" type="fixed">
    <origin rpy="0.0 0.0 0.0" xyz="0.244 0.0 0.20858"/>
    <parent link="base_link"/>
    <child link="base_laser_front_link"/>
  </joint>
  <link name="base_laser_front_link" type="laser">
    <inertial>
      <mass value="1.2"/>
      <origin rpy="0 0 0" xyz="0 0 0"/>
      <inertia ixx="0.0029999987999999997" ixy="0.0" ixz="0.0" iyy="0.0029999987999999997" iyz="0.0" izz="0.0015"/>
    </inertial>
    <visual>
      <origin rpy="0 0 0" xyz="0 0 0"/>
      <geometry>
        <mesh filename="file:///home/nhg-yc/ros2_ws/cob_ws/install/cob_description/share/cob_description/meshes/sensors/sick_s300_laser.dae"/>
        <!--box size="0.001 0.001 0.001" /-->
      </geometry>
      <material name="IPA/LightGrey"/>
    </visual>
    <collision>
      <origin rpy="0 0 0" xyz="0 0 0"/>
      <geometry>
        <mesh filename="file:///home/nhg-yc/ros2_ws/cob_ws/install/cob_description/share/cob_description/meshes/sensors/sick_s300_laser_collision.stl"/>
      </geometry>
    </collision>
  </link>
  <gazebo reference="base_laser_front_link">
    <sensor name="base_laser_front" type="ray">
      <always_on>true</always_on>
      <update_rate>12.0</update_rate>
      <pose>0 0 0 0 0 0</pose>
      <visualize>true</visualize>
      <ray>
        <scan>
          <horizontal>
            <samples>541</samples>
            <resolution>1.0</resolution>
            <min_angle>-2.3562</min_angle>
            <max_angle>2.3562</max_angle>
          </horizontal>
        </scan>
        <range>
          <min>0.05</min>
          <max>29.5</max>
          <resolution>0.03</resolution>
        </range>
        <noise>
          <type>gaussian</type>
          <mean>0.0</mean>
          <stddev>0.02</stddev>
        </noise>
      </ray>
      <plugin filename="libgazebo_ros_ray_sensor.so" name="gazebo_ros_base_laser_front_controller">
        <!-- <topicName>${name}/scan_raw</topicName> -->
        <ros>
          <namespace>base_laser_front</namespace>
          <remapping>~/out:=scan_raw</remapping>
        </ros>
        <output_type>sensor_msgs/LaserScan</output_type>
        <frameName>base_laser_front_link</frameName>
      </plugin>
    </sensor>
  </gazebo>
  <joint name="base_laser_left_joint" type="fixed">
    <origin rpy="0.0 0.0 2.094" xyz="-0.122 0.21131 0.20858"/>
    <parent link="base_link"/>
    <child link="base_laser_left_link"/>
  </joint>
  <link name="base_laser_left_link" type="laser">
    <inertial>
      <mass value="1.2"/>
      <origin rpy="0 0 0" xyz="0 0 0"/>
      <inertia ixx="0.0029999987999999997" ixy="0.0" ixz="0.0" iyy="0.0029999987999999997" iyz="0.0" izz="0.0015"/>
    </inertial>
    <visual>
      <origin rpy="0 0 0" xyz="0 0 0"/>
      <geometry>
        <mesh filename="file:///home/nhg-yc/ros2_ws/cob_ws/install/cob_description/share/cob_description/meshes/sensors/sick_s300_laser.dae"/>
        <!--box size="0.001 0.001 0.001" /-->
      </geometry>
      <material name="IPA/LightGrey"/>
    </visual>
    <collision>
      <origin rpy="0 0 0" xyz="0 0 0"/>
      <geometry>
        <mesh filename="file:///home/nhg-yc/ros2_ws/cob_ws/install/cob_description/share/cob_description/meshes/sensors/sick_s300_laser_collision.stl"/>
      </geometry>
    </collision>
  </link>
  <gazebo reference="base_laser_left_link">
    <sensor name="base_laser_left" type="ray">
      <always_on>true</always_on>
      <update_rate>12.0</update_rate>
      <pose>0 0 0 0 0 0</pose>
      <visualize>true</visualize>
      <ray>
        <scan>
          <horizontal>
            <samples>541</samples>
            <resolution>1.0</resolution>
            <min_angle>-2.3562</min_angle>
            <max_angle>2.3562</max_angle>
          </horizontal>
        </scan>
        <range>
          <min>0.05</min>
          <max>29.5</max>
          <resolution>0.03</resolution>
        </range>
        <noise>
          <type>gaussian</type>
          <mean>0.0</mean>
          <stddev>0.02</stddev>
        </noise>
      </ray>
      <plugin filename="libgazebo_ros_ray_sensor.so" name="gazebo_ros_base_laser_left_controller">
        <!-- <topicName>${name}/scan_raw</topicName> -->
        <ros>
          <namespace>base_laser_left</namespace>
          <remapping>~/out:=scan_raw</remapping>
        </ros>
        <output_type>sensor_msgs/LaserScan</output_type>
        <frameName>base_laser_left_link</frameName>
      </plugin>
    </sensor>
  </gazebo>
  <joint name="base_laser_right_joint" type="fixed">
    <origin rpy="0.0 0.0 -2.094" xyz="-0.122 -0.21131 0.20858"/>
    <parent link="base_link"/>
    <child link="base_laser_right_link"/>
  </joint>
  <link name="base_laser_right_link" type="laser">
    <inertial>
      <mass value="1.2"/>
      <origin rpy="0 0 0" xyz="0 0 0"/>
      <inertia ixx="0.0029999987999999997" ixy="0.0" ixz="0.0" iyy="0.0029999987999999997" iyz="0.0" izz="0.0015"/>
    </inertial>
    <visual>
      <origin rpy="0 0 0" xyz="0 0 0"/>
      <geometry>
        <mesh filename="file:///home/nhg-yc/ros2_ws/cob_ws/install/cob_description/share/cob_description/meshes/sensors/sick_s300_laser.dae"/>
        <!--box size="0.001 0.001 0.001" /-->
      </geometry>
      <material name="IPA/LightGrey"/>
    </visual>
    <collision>
      <origin rpy="0 0 0" xyz="0 0 0"/>
      <geometry>
        <mesh filename="file:///home/nhg-yc/ros2_ws/cob_ws/install/cob_description/share/cob_description/meshes/sensors/sick_s300_laser_collision.stl"/>
      </geometry>
    </collision>
  </link>
  <gazebo reference="base_laser_right_link">
    <sensor name="base_laser_right" type="ray">
      <always_on>true</always_on>
      <update_rate>12.0</update_rate>
      <pose>0 0 0 0 0 0</pose>
      <visualize>true</visualize>
      <ray>
        <scan>
          <horizontal>
            <samples>541</samples>
            <resolution>1.0</resolution>
            <min_angle>-2.3562</min_angle>
            <max_angle>2.3562</max_angle>
          </horizontal>
        </scan>
        <range>
          <min>0.05</min>
          <max>29.5</max>
          <resolution>0.03</resolution>
        </range>
        <noise>
          <type>gaussian</type>
          <mean>0.0</mean>
          <stddev>0.02</stddev>
        </noise>
      </ray>
      <plugin filename="libgazebo_ros_ray_sensor.so" name="gazebo_ros_base_laser_right_controller">
        <!-- <topicName>${name}/scan_raw</topicName> -->
        <ros>
          <namespace>base_laser_right</namespace>
          <remapping>~/out:=scan_raw</remapping>
        </ros>
        <output_type>sensor_msgs/LaserScan</output_type>
        <frameName>base_laser_right_link</frameName>
      </plugin>
    </sensor>
  </gazebo>
  <!-- ros_control plugin -->

  <!-- torso -->
  <joint name="torso_base_joint" type="fixed">
    <origin rpy="0.0 0.0 0.0" xyz="0.0 0.0 0.26411"/>
    <parent link="base_link"/>
    <child link="torso_base_link"/>
  </joint>
  <link name="torso_base_link">
    <inertial>
      <mass value="0.01"/>
      <origin xyz="0 0 0"/>
      <inertia ixx="0.001" ixy="0.0" ixz="0.0" iyy="0.001" iyz="0.0" izz="0.001"/>
    </inertial>
    <!--
       <xacro:cylinder_inertial radius="0.300" length="0.046" mass="5.0">
        <origin xyz="0.03 0.08 0.01" rpy="0 0 0" />
      </xacro:cylinder_inertial>
-->
    <visual>
      <origin rpy="0 0 0" xyz="0 0 0"/>
      <geometry>
        <box size="0.001 0.001 0.001"/>
      </geometry>
    </visual>
    <collision>
      <origin rpy="0 0 0" xyz="0 0 0"/>
      <geometry>
        <box size="0.001 0.001 0.001"/>
      </geometry>
    </collision>
  </link>
  <joint name="torso_1_joint" type="fixed">
    <origin rpy="0 0 0" xyz="0 0 0.04642"/>
    <parent link="torso_base_link"/>
    <child link="torso_1_link"/>
  </joint>
  <link name="torso_1_link">
    <inertial>
      <mass value="0.01"/>
      <origin xyz="0 0 0"/>
      <inertia ixx="0.001" ixy="0.0" ixz="0.0" iyy="0.001" iyz="0.0" izz="0.001"/>
    </inertial>
    <!--
      <xacro:hollow_spherical_cap_inertial r="0.295" h="0.075" t="0.010" mass="6">
        <origin xyz="0 0 ${0.075/2}" rpy="0 0 0"/>
      </xacro:hollow_spherical_cap_inertial>
-->
    <visual>
      <origin rpy="0 0 0" xyz="0 0 0"/>
      <geometry>
        <box size="0.001 0.001 0.001"/>
      </geometry>
    </visual>
    <collision>
      <origin rpy="0 0 0" xyz="0 0 0"/>
      <geometry>
        <box size="0.001 0.001 0.001"/>
      </geometry>
    </collision>
  </link>
  <joint name="torso_2_joint" type="revolute">
    <origin rpy="0.5236 0 0" xyz="0 0.14734 0.07547"/>
    <parent link="torso_1_link"/>
    <child link="torso_2_link"/>
    <axis xyz="0 0 1"/>
    <limit effort="100" lower="-6.2831" upper="6.2831" velocity="1.4"/>
  </joint>
  <link name="torso_2_link">
    <inertial>
      <mass value="0.01"/>
      <origin xyz="0 0 0"/>
      <inertia ixx="0.001" ixy="0.0" ixz="0.0" iyy="0.001" iyz="0.0" izz="0.001"/>
    </inertial>
    <!--
      <xacro:spherical_cap_inertial r="0.295" h="0.075" mass="19.5">
        <origin xyz="0.034 0.102 0.092" rpy="0.5236 0 0"/>
      </xacro:spherical_cap_inertial>
-->
    <visual>
      <origin rpy="0 0 0" xyz="0 0 0"/>
      <geometry>
        <box size="0.001 0.001 0.001"/>
      </geometry>
    </visual>
    <collision>
      <origin rpy="0 0 0" xyz="0 0 0"/>
      <geometry>
        <box size="0.001 0.001 0.001"/>
      </geometry>
    </collision>
  </link>
  <joint name="torso_3_joint" type="revolute">
    <origin rpy="-0.5236 0 0" xyz="0 -0.09228 0.13477"/>
    <parent link="torso_2_link"/>
    <child link="torso_3_link"/>
    <axis xyz="0 0 1"/>
    <limit effort="100" lower="-6.2831" upper="6.2831" velocity="1.4"/>
  </joint>
  <link name="torso_3_link">
    <inertial>
      <mass value="0.01"/>
      <origin xyz="0 0 0"/>
      <inertia ixx="0.001" ixy="0.0" ixz="0.0" iyy="0.001" iyz="0.0" izz="0.001"/>
    </inertial>
    <!--
      <xacro:cylinder_inertial radius="0.250" length="0.610" mass="23.8">
        <origin xyz="-0.028 0.005 0.233" rpy="0 0 0" />
      </xacro:cylinder_inertial>
-->
    <visual>
      <origin rpy="0 0 0" xyz="0 0 0"/>
      <geometry>
        <mesh filename="file:///home/nhg-yc/ros2_ws/cob_ws/install/cob_description/share/cob_description/meshes/cob4_torso/torso_link.dae"/>
      </geometry>
    </visual>
    <collision>
      <origin rpy="0 0 0" xyz="0 0 0"/>
      <geometry>
        <mesh filename="file:///home/nhg-yc/ros2_ws/cob_ws/install/cob_description/share/cob_description/meshes/cob4_torso/torso_link_collision.stl"/>
      </geometry>
    </collision>
  </link>
  <joint name="torso_center_joint" type="fixed">
    <origin rpy="0 0 0" xyz="0.0 0.0 0.18566"/>
    <parent link="torso_3_link"/>
    <child link="torso_center_link"/>
  </joint>
  <link name="torso_center_link">
    <inertial>
      <mass value="0.01"/>
      <origin xyz="0 0 0"/>
      <inertia ixx="0.001" ixy="0.0" ixz="0.0" iyy="0.001" iyz="0.0" izz="0.001"/>
    </inertial>
    <visual>
      <origin rpy="0 0 0" xyz="0 0 0"/>
      <geometry>
        <box size="0.001 0.001 0.001"/>
      </geometry>
    </visual>
    <collision>
      <origin rpy="0 0 0" xyz="0 0 0"/>
      <geometry>
        <box size="0.001 0.001 0.001"/>
      </geometry>
    </collision>
  </link>
  <gazebo reference="torso_base_link">
    <gravity>true</gravity>
    <self_collide>false</self_collide>
  </gazebo>
  <gazebo reference="torso_1_link">
    <gravity>true</gravity>
    <self_collide>false</self_collide>
  </gazebo>
  <gazebo reference="torso_2_link">
    <gravity>true</gravity>
    <self_collide>false</self_collide>
  </gazebo>
  <gazebo reference="torso_3_link">
    <gravity>true</gravity>
    <self_collide>false</self_collide>
  </gazebo>
  <transmission name="torso_2_trans">
    <type>transmission_interface/SimpleTransmission</type>
    <joint name="torso_2_joint">
      <hardwareInterface>hardware_interface/PositionJointInterface</hardwareInterface>
      <hardwareInterface>hardware_interface/VelocityJointInterface</hardwareInterface>
      <!--hardwareInterface>hardware_interface/EffortJointInterface</hardwareInterface-->
    </joint>
    <actuator name="torso_2_motor">
      <mechanicalReduction>1</mechanicalReduction>
    </actuator>
  </transmission>
  <transmission name="torso_3_trans">
    <type>transmission_interface/SimpleTransmission</type>
    <joint name="torso_3_joint">
      <hardwareInterface>hardware_interface/PositionJointInterface</hardwareInterface>
      <hardwareInterface>hardware_interface/VelocityJointInterface</hardwareInterface>
      <!--hardwareInterface>hardware_interface/EffortJointInterface</hardwareInterface-->
    </joint>
    <actuator name="torso_3_motor">
      <mechanicalReduction>1</mechanicalReduction>
    </actuator>
  </transmission>
  <ros2_control name="GazeboSystem" type="system">
    <hardware>
      <plugin>gazebo_ros2_control/GazeboSystem</plugin>
    </hardware>
    <joint name="torso_2_joint">
      <command_interface name="position">
        <param name="min">-5</param>
        <param name="max">5</param>
      </command_interface>
      <state_interface name="position">
        <param name="initial_value">0.0</param>
      </state_interface>
      <state_interface name="velocity"/>
      <state_interface name="effort"/>
    </joint>
    <joint name="torso_3_joint">
      <command_interface name="position">
        <param name="min">-5</param>
        <param name="max">5</param>
      </command_interface>
      <state_interface name="position">
        <param name="initial_value">0.0</param>
      </state_interface>
      <state_interface name="velocity"/>
      <state_interface name="effort"/>
    </joint>
  </ros2_control>
  <gazebo>
    <plugin filename="libgazebo_ros2_control.so" name="gazebo_ros2_control">
      <parameters>$(find tricycle_sim)/config/cob_torso_0411.yaml</parameters>
    </plugin>
  </gazebo>
  
  
  
</robot>
