<?xml version="1.0" ?>
<!-- =================================================================================== -->
<!-- |    This document was autogenerated by xacro from cob4-25.urdf-base.xacro        | -->
<!-- |    EDITING THIS FILE BY HAND IS NOT RECOMMENDED                                 | -->
<!-- =================================================================================== -->
<robot name="cob4-25">
  <material name="IPA/LightGrey">
    <color rgba="0.7 0.7 0.7 1.0"/>
  </material>
  <material name="IPA/DarkGrey">
    <color rgba="0.4 0.4 0.4 1.0"/>
  </material>
  <material name="IPA/Black">
    <color rgba="0.0 0.0 0.0 1.0"/>
  </material>
  <material name="IPA/Metall">
    <color rgba="0.7 0.7 0.7 1.0"/>
  </material>
  <material name="IPA/YellowRubber">
    <color rgba="0.4 0.27 0.16 1.0"/>
  </material>
  <material name="IPA/Orange">
    <color rgba="1.0 0.4 0.0 1.0"/>
  </material>
  <material name="IPA/Blue">
    <color rgba="0.0 0.0 0.5 1.0"/>
  </material>

  <!-- <link name="base_pivot_link"/>
  <joint name="base_pivot_joint" type="fixed">
    <origin rpy="0 0 0" xyz="-0.12422 0.0 0.0"/>
    <parent link="base_pivot_link"/>
    <child link="base_footprint"/>
  </joint> -->
  <link name="base_footprint"/>
  <joint name="base_footprint_joint" type="fixed">
    <origin rpy="0 0 0" xyz="0 0 0"/>
    <parent link="base_footprint"/>
    <child link="base_link"/>
  </joint>
  <link name="base_link"/>
  <joint name="base_chassis_joint" type="fixed">
    <origin rpy="0 0 0" xyz="0 0 0"/>
    <parent link="base_link"/>
    <child link="base_chassis_link"/>
  </joint>
  <link name="base_chassis_link">
    <inertial>
      <origin xyz="0 0 0"/>
      <mass value="100"/>
      <inertia ixx="5.652232699207" ixy="-0.009719934438" ixz="1.293988226423" iyy="5.669473158652" iyz="-0.007379583694" izz="3.683196351726"/>
    </inertial>
    <visual>
      <origin rpy="0 0 0" xyz="0 0 0"/>
      <geometry>
        <!-- <mesh filename="package://cob_description/meshes/cob4_base/base.dae"/> -->
        <mesh filename="file:///home/nhg-yc/ros2_ws/tricycle_ws/install/tricycle_sim/share/tricycle_sim/meshes/cob4_base/base.dae"/>
        <!--box size="0.01 0.01 0.01" /-->
      </geometry>
    </visual>
    <collision>
      <origin rpy="0 0 0" xyz="0 0 0"/>
      <geometry>
        <mesh filename="file:///home/nhg-yc/ros2_ws/tricycle_ws/install/tricycle_sim/share/tricycle_sim/meshes/cob4_base/base_collision.stl"/>
        <!--box size="0.01 0.01 0.01" /-->
      </geometry>
    </collision>
  </link>
  <joint name="base_charger_joint" type="fixed">
    <origin rpy="0 0 0" xyz="0.2992 0.0 0.09089"/>
    <parent link="base_chassis_link"/>
    <child link="base_charger_link"/>
  </joint>
  <link name="base_charger_link"/>
  <joint name="fl_caster_rotation_joint" type="fixed">
    <origin rpy="0 0 0" xyz="0.12422 0.21515 0.0782"/>
    <parent link="base_chassis_link"/>
    <child link="fl_caster_rotation_link"/>
  </joint>
  <link name="fl_caster_rotation_link">
    <inertial>
      <origin xyz="0 0 0"/>
      <mass value="5.9"/>
      <inertia ixx="0.04" ixy="-0.0007" ixz="0.0" iyy="0.02" iyz="-0.000004" izz="0.05"/>
    </inertial>
    <visual>
      <geometry>
        <mesh filename="file:///home/nhg-yc/ros2_ws/tricycle_ws/install/tricycle_sim/share/tricycle_sim/meshes/drive_wheel/caster.stl"/>
      </geometry>
      <material name="IPA/LightGrey"/>
    </visual>
    <collision>
      <geometry>
        <box size="0.001 0.001 0.001"/>
      </geometry>
    </collision>
  </link>
  <joint name="fl_caster_r_wheel_joint" type="continuous">
    <origin rpy="0 0 0" xyz="0 -0.0 0"/>
    <parent link="fl_caster_rotation_link"/>
    <child link="fl_caster_r_wheel_link"/>
    <axis xyz="0 1 0"/>
    <!-- <safety_controller k_velocity="10"/>
    <limit effort="0.0" velocity="19.95"/>
    <dynamics damping="0.0" friction="0.0"/> -->
  </joint>
  <link name="fl_caster_r_wheel_link">
    <inertial>
      <origin xyz="0 0 0"/>
      <mass value="0.44036"/>
      <inertia ixx="0.012411765597" ixy="-0.000711733678" ixz="0.00050272983" iyy="0.015218160428" iyz="-0.000004273467" izz="0.011763977943"/>
    </inertial>
    <visual>
      <geometry>
        <mesh filename="file:///home/nhg-yc/ros2_ws/tricycle_ws/install/tricycle_sim/share/tricycle_sim/meshes/drive_wheel/wheel.dae"/>
      </geometry>
    </visual>
    <collision>
      <geometry>
        <mesh filename="file:///home/nhg-yc/ros2_ws/tricycle_ws/install/tricycle_sim/share/tricycle_sim/meshes/drive_wheel/wheel.stl"/>
        <!-- <cylinder radius="0.4" length="0.1"/> -->
      </geometry>
    </collision>
  </link>
  <gazebo reference="fl_caster_r_wheel_link">
    <gravity>true</gravity>
    <self_collide>false</self_collide>
  </gazebo>
  <gazebo reference="fl_caster_rotation_link">
    <gravity>true</gravity>
    <self_collide>false</self_collide>
    <material value="IPA/Metal"/>
  </gazebo>
  <joint name="b_caster_rotation_joint" type="continuous">
    <origin rpy="0 0 0" xyz="-0.24844 0.0 0.0782"/>
    <parent link="base_chassis_link"/>
    <child link="b_caster_rotation_link"/>
    <axis xyz="0 0 1"/>
    <!-- <safety_controller k_velocity="10"/>
    <limit effort="100" velocity="12.0"/>
    <dynamics damping="0.0" friction="0.0"/> -->
  </joint>
  <link name="b_caster_rotation_link">
    <inertial>
      <origin xyz="0 0 0"/>
      <mass value="5.9"/>
      <inertia ixx="0.04" ixy="-0.0007" ixz="0.0" iyy="0.02" iyz="-0.000004" izz="0.05"/>
    </inertial>
    <visual>
      <geometry>
        <mesh filename="file:///home/nhg-yc/ros2_ws/tricycle_ws/install/tricycle_sim/share/tricycle_sim/meshes/drive_wheel/caster.stl"/>
      </geometry>
      <material name="IPA/LightGrey"/>
    </visual>
    <collision>
      <geometry>
        <box size="0.001 0.001 0.001"/>
      </geometry>
    </collision>
  </link>
  <transmission name="b_caster_rotation_trans">
    <type>transmission_interface/SimpleTransmission</type>
    <joint name="b_caster_rotation_joint">
      <hardwareInterface>hardware_interface/PositionJointInterface</hardwareInterface>
      <hardwareInterface>hardware_interface/VelocityJointInterface</hardwareInterface>
    </joint>
    <actuator name="b_caster_rotation_motor">
      <mechanicalReduction>-79.23809523809524</mechanicalReduction>
    </actuator>
  </transmission>
  <joint name="b_caster_r_wheel_joint" type="continuous">
    <origin rpy="0 0 0" xyz="0 -0.0 0"/>
    <parent link="b_caster_rotation_link"/>
    <child link="b_caster_r_wheel_link"/>
    <axis xyz="0 1 0"/>
    <!-- <safety_controller k_velocity="10"/>
    <limit effort="100" velocity="19.95"/>
    <dynamics damping="0.0" friction="0.0"/> -->
  </joint>
  <link name="b_caster_r_wheel_link">
    <inertial>
      <origin xyz="0 0 0"/>
      <mass value="0.44036"/>
      <inertia ixx="0.012411765597" ixy="-0.000711733678" ixz="0.00050272983" iyy="0.015218160428" iyz="-0.000004273467" izz="0.011763977943"/>
    </inertial>
    <visual>
      <geometry>
        <mesh filename="file:///home/nhg-yc/ros2_ws/tricycle_ws/install/tricycle_sim/share/tricycle_sim/meshes/drive_wheel/wheel.dae"/>
      </geometry>
    </visual>
    <collision>
      <geometry>
        <mesh filename="file:///home/nhg-yc/ros2_ws/tricycle_ws/install/tricycle_sim/share/tricycle_sim/meshes/drive_wheel/wheel.stl"/>
      </geometry>
    </collision>
  </link>
  <gazebo reference="b_caster_r_wheel_link">
    <gravity>true</gravity>
    <self_collide>false</self_collide>
  </gazebo>
  <transmission name="b_caster_r_wheel_trans">
    <type>transmission_interface/SimpleTransmission</type>
    <joint name="b_caster_r_wheel_joint">
      <hardwareInterface>hardware_interface/VelocityJointInterface</hardwareInterface>
    </joint>
    <actuator name="b_caster_r_wheel_motor">
      <mechanicalReduction>-79.23809523809524</mechanicalReduction>
    </actuator>
  </transmission>
  <gazebo reference="b_caster_rotation_link">
    <gravity>true</gravity>
    <self_collide>false</self_collide>
    <material value="IPA/Metal"/>
  </gazebo>
  <joint name="fr_caster_rotation_joint" type="fixed">
    <origin rpy="0 0 0" xyz="0.12422 -0.21515 0.0782"/>
    <parent link="base_chassis_link"/>
    <child link="fr_caster_rotation_link"/>
  </joint>
  <link name="fr_caster_rotation_link">
    <inertial>
      <origin xyz="0 0 0"/>
      <mass value="5.9"/>
      <inertia ixx="0.04" ixy="-0.0007" ixz="0.0" iyy="0.02" iyz="-0.000004" izz="0.05"/>
    </inertial>
    <visual>
      <geometry>
        <mesh filename="file:///home/nhg-yc/ros2_ws/tricycle_ws/install/tricycle_sim/share/tricycle_sim/meshes/drive_wheel/caster.stl"/>
      </geometry>
      <material name="IPA/LightGrey"/>
    </visual>
    <collision>
      <geometry>
        <box size="0.001 0.001 0.001"/>
      </geometry>
    </collision>
  </link>
  <joint name="fr_caster_r_wheel_joint" type="continuous">
    <origin rpy="0 0 0" xyz="0 -0.0 0"/>
    <parent link="fr_caster_rotation_link"/>
    <child link="fr_caster_r_wheel_link"/>
    <axis xyz="0 1 0"/>
    <!-- <safety_controller k_velocity="10"/>
    <limit effort="0.0" velocity="19.95"/>
    <dynamics damping="0.0" friction="0.0"/> -->
  </joint>
  <link name="fr_caster_r_wheel_link">
    <inertial>
      <origin xyz="0 0 0"/>
      <mass value="0.44036"/>
      <inertia ixx="0.012411765597" ixy="-0.000711733678" ixz="0.00050272983" iyy="0.015218160428" iyz="-0.000004273467" izz="0.011763977943"/>
    </inertial>
    <visual>
      <geometry>
        <mesh filename="file:///home/nhg-yc/ros2_ws/tricycle_ws/install/tricycle_sim/share/tricycle_sim/meshes/drive_wheel/wheel.dae"/>
      </geometry>
    </visual>
    <collision>
      <geometry>
        <mesh filename="file:///home/nhg-yc/ros2_ws/tricycle_ws/install/tricycle_sim/share/tricycle_sim/meshes/drive_wheel/wheel.stl"/>
      </geometry>
    </collision>
  </link>
  <gazebo reference="fr_caster_r_wheel_link">
    <gravity>true</gravity>
    <self_collide>false</self_collide>
  </gazebo>
  <gazebo reference="fr_caster_rotation_link">
    <gravity>true</gravity>
    <self_collide>false</self_collide>
    <material value="IPA/Metal"/>
  </gazebo>
  <gazebo reference="base_link">
    <gravity>true</gravity>
    <self_collide>false</self_collide>
    <sensor name="base_contact_sensor" type="contact">
      <always_on>true</always_on>
      <update_rate>100.0</update_rate>
      <contact>
        <collision>base_link_collision</collision>
        <topic>base_bumper</topic>
      </contact>
      <plugin filename="libgazebo_ros_bumper.so" name="base_gazebo_ros_bumper_controller">
        <frameName>world</frameName>
        <bumperTopicName>base_bumper</bumperTopicName>
      </plugin>
    </sensor>
  </gazebo>
  <gazebo>
    <plugin filename="libgazebo_ros_p3d.so" name="p3d_base_controller">
      <alwaysOn>true</alwaysOn>
      <updateRate>100.0</updateRate>
      <!-- <body_name>base_footprint</body_name> -->
      <body_name>base_pivot_link</body_name>
      <topicName>base_pose_ground_truth</topicName>
      <frameName>map</frameName>
      <xyzOffsets>25.7 25.7 0</xyzOffsets>
      <rpyOffsets>0 0 0</rpyOffsets>
      <gaussianNoise>0.01</gaussianNoise>
    </plugin>
    <canonicalBody>base_footprint</canonicalBody>
  </gazebo>
  <joint name="base_laser_front_joint" type="fixed">
    <origin rpy="0.0 0.0 0.0" xyz="0.244 0.0 0.20858"/>
    <parent link="base_link"/>
    <child link="base_laser_front_link"/>
  </joint>
  <link name="base_laser_front_link" type="laser">
    <inertial>
      <mass value="1.2"/>
      <origin rpy="0 0 0" xyz="0 0 0"/>
      <inertia ixx="0.0029999987999999997" ixy="0.0" ixz="0.0" iyy="0.0029999987999999997" iyz="0.0" izz="0.0015"/>
    </inertial>
    <visual>
      <origin rpy="0 0 0" xyz="0 0 0"/>
      <geometry>
        <mesh filename="file:///home/nhg-yc/ros2_ws/tricycle_ws/install/tricycle_sim/share/tricycle_sim/meshes/sensors/sick_s300_laser.dae"/>

      </geometry>
      <material name="IPA/LightGrey"/>
    </visual>
    <collision>
      <origin rpy="0 0 0" xyz="0 0 0"/>
      <geometry>
        <mesh filename="file:///home/nhg-yc/ros2_ws/tricycle_ws/install/tricycle_sim/share/tricycle_sim/meshes/sensors/sick_s300_laser_collision.stl"/>
      </geometry>
    </collision>
  </link>
  <gazebo reference="base_laser_front_link">
    <sensor name="base_laser_front" type="ray">
      <always_on>true</always_on>
      <update_rate>12.0</update_rate>
      <pose>0 0 0 0 0 0</pose>
      <visualize>true</visualize>
      <ray>
        <scan>
          <horizontal>
            <samples>541</samples>
            <resolution>1.0</resolution>
            <min_angle>-1.5708</min_angle>
            <max_angle>1.5708</max_angle>
          </horizontal>
        </scan>
        <range>
          <min>0.05</min>
          <max>29.5</max>
          <resolution>0.03</resolution>
        </range>
        <noise>
          <type>gaussian</type>
          <mean>0.0</mean>
          <stddev>0.02</stddev>
        </noise>
      </ray>
      <!-- <plugin filename="libgazebo_ros_laser.so" name="gazebo_ros_base_laser_front_controller">
        <topicName>base_laser_front/scan_raw</topicName>
        <frameName>base_laser_front_link</frameName>
      </plugin> -->
      <plugin name="gazebo_ros_base_laser_front_controller" filename="libgazebo_ros_ray_sensor.so">
        <ros>
          <namespace>base_laser_front</namespace>
          <remapping>~/out:=scan_raw</remapping>
        </ros>
        <output_type>sensor_msgs/LaserScan</output_type>
      </plugin>
    </sensor>
  </gazebo>
  <joint name="base_laser_left_joint" type="fixed">
    <origin rpy="0.0 0.0 2.094" xyz="-0.122 0.21131 0.20858"/>
    <parent link="base_link"/>
    <child link="base_laser_left_link"/>
  </joint>
  <link name="base_laser_left_link" type="laser">
    <inertial>
      <mass value="1.2"/>
      <origin rpy="0 0 0" xyz="0 0 0"/>
      <inertia ixx="0.0029999987999999997" ixy="0.0" ixz="0.0" iyy="0.0029999987999999997" iyz="0.0" izz="0.0015"/>
    </inertial>
    <visual>
      <origin rpy="0 0 0" xyz="0 0 0"/>
      <geometry>
        <mesh filename="file:///home/nhg-yc/ros2_ws/tricycle_ws/install/tricycle_sim/share/tricycle_sim/meshes/sensors/sick_s300_laser.dae"/>

      </geometry>
      <material name="IPA/LightGrey"/>
    </visual>
    <collision>
      <origin rpy="0 0 0" xyz="0 0 0"/>
      <geometry>
        <mesh filename="file:///home/nhg-yc/ros2_ws/tricycle_ws/install/tricycle_sim/share/tricycle_sim/meshes/sensors/sick_s300_laser_collision.stl"/>
      </geometry>
    </collision>
  </link>
  <gazebo reference="base_laser_left_link">
    <sensor name="base_laser_left" type="ray">
      <always_on>true</always_on>
      <update_rate>12.0</update_rate>
      <pose>0 0 0 0 0 0</pose>
      <visualize>false</visualize>
      <ray>
        <scan>
          <horizontal>
            <samples>541</samples>
            <resolution>1.0</resolution>
            <min_angle>-2.3562</min_angle>
            <max_angle>2.3562</max_angle>
          </horizontal>
        </scan>
        <range>
          <min>0.05</min>
          <max>29.5</max>
          <resolution>0.03</resolution>
        </range>
        <noise>
          <type>gaussian</type>
          <mean>0.0</mean>
          <stddev>0.02</stddev>
        </noise>
      </ray>
      <!-- <plugin filename="libgazebo_ros_laser.so" name="gazebo_ros_base_laser_left_controller">
        <topicName>base_laser_left/scan_raw</topicName>
        <frameName>base_laser_left_link</frameName>
      </plugin> -->
      <plugin name="gazebo_ros_base_laser_left_controller" filename="libgazebo_ros_ray_sensor.so">
        <ros>
          <namespace>base_laser_left</namespace>
          <remapping>~/out:=scan_raw</remapping>
        </ros>
        <output_type>sensor_msgs/LaserScan</output_type>
      </plugin>
    </sensor>
  </gazebo>
  <joint name="base_laser_right_joint" type="fixed">
    <origin rpy="0.0 0.0 -2.094" xyz="-0.122 -0.21131 0.20858"/>
    <parent link="base_link"/>
    <child link="base_laser_right_link"/>
  </joint>
  <link name="base_laser_right_link" type="laser">
    <inertial>
      <mass value="1.2"/>
      <origin rpy="0 0 0" xyz="0 0 0"/>
      <inertia ixx="0.0029999987999999997" ixy="0.0" ixz="0.0" iyy="0.0029999987999999997" iyz="0.0" izz="0.0015"/>
    </inertial>
    <visual>
      <origin rpy="0 0 0" xyz="0 0 0"/>
      <geometry>
        <mesh filename="file:///home/nhg-yc/ros2_ws/tricycle_ws/install/tricycle_sim/share/tricycle_sim/meshes/sensors/sick_s300_laser.dae"/>
      </geometry>
      <material name="IPA/LightGrey"/>
    </visual>
    <collision>
      <origin rpy="0 0 0" xyz="0 0 0"/>
      <geometry>
        <mesh filename="file:///home/nhg-yc/ros2_ws/tricycle_ws/install/tricycle_sim/share/tricycle_sim/meshes/sensors/sick_s300_laser_collision.stl"/>
      </geometry>
    </collision>
  </link>
  <gazebo reference="base_laser_right_link">
    <sensor name="base_laser_right" type="ray">
      <always_on>true</always_on>
      <update_rate>12.0</update_rate>
      <pose>0 0 0 0 0 0</pose>
      <visualize>false</visualize>
      <ray>
        <scan>
          <horizontal>
            <samples>541</samples>
            <resolution>1.0</resolution>
            <min_angle>-2.3562</min_angle>
            <max_angle>2.3562</max_angle>
          </horizontal>
        </scan>
        <range>
          <min>0.05</min>
          <max>29.5</max>
          <resolution>0.03</resolution>
        </range>
        <noise>
          <type>gaussian</type>
          <mean>0.0</mean>
          <stddev>0.02</stddev>
        </noise>
      </ray>
      <!-- <plugin filename="libgazebo_ros_laser.so" name="gazebo_ros_base_laser_right_controller">
        <topicName>base_laser_right/scan_raw</topicName>
        <frameName>base_laser_right_link</frameName>
      </plugin> -->
      <plugin name="gazebo_ros_base_laser_right_controller" filename="libgazebo_ros_ray_sensor.so">
        <ros>
          <namespace>base_laser_right</namespace>
          <remapping>~/out:=scan_raw</remapping>
        </ros>
        <output_type>sensor_msgs/LaserScan</output_type>
      </plugin>
    </sensor>
  </gazebo>
  
  <!-- ros_control plugin -->
  <!-- <gazebo>
    <plugin name="object_controller" filename="libgazebo_ros_planar_move.so">
      <commandTopic>cmd_vel</commandTopic>
      <odometryTopic>odom</odometryTopic>
      <odometryFrame>odom</odometryFrame>
      <odometryRate>20.0</odometryRate>
      <robotBaseFrame>base_footprint</robotBaseFrame>
    </plugin>
  </gazebo> -->
  <ros2_control name="GazeboSystem" type="system">
    <hardware>
      <plugin>gazebo_ros2_control/GazeboSystem</plugin>
    </hardware>
    <joint name="b_caster_rotation_joint">
      <command_interface name="position" />
      <state_interface name="position" />
    </joint>
    <joint name="b_caster_r_wheel_joint">
      <command_interface name="velocity" />
      <state_interface name="velocity" />
      <state_interface name="position" />
    </joint>
  </ros2_control>

  <gazebo>
    <plugin filename="libgazebo_ros2_control.so" name="gazebo_ros2_control">
      <parameters>$(find tricycle_sim)/config/cob_tricycle_drive_controller.yaml</parameters>
    </plugin>
  </gazebo>  
</robot>
