<?xml version="1.0"?>
<robot name="tricycle_drive" xmlns:xacro="http://ros.org/wiki/xacro">
  <material name="Black">
    <color rgba="0 0 0 1" />
  </material>
  <material name="Grey">
    <color rgba="0.8 0.8 0.8 1" />
  </material>
  <material name="Orange">
    <color rgba="1 0.6 0 1" />
  </material>
  <material name="White">
    <color rgba="1 1 1 1" />
  </material>

  <link name="base_link" />

  <link name="base_footprint" />
  <joint name="base_joint" type="fixed">
    <parent link="base_link"/>
    <child link="base_footprint"/>
    <origin xyz="0 0 0" rpy="0 0 0"/>
  </joint>

  <link name="odom" />
  <joint name="odom_joint" type="fixed">
    <parent link="base_link"/>
    <child link="odom"/>
    <origin xyz="0.0 0.0 0.0" rpy="0 0 0"/>
  </joint>


  <!-- Chassis -->
  <link name="chassis">
    <collision>
      <origin xyz="0 0 0" rpy="0 0 0" />
      <geometry>
        <box size="2 1 0.5" />
      </geometry>
    </collision>

    <visual>
      <origin xyz="0 0 0" rpy="0 0 0" />
      <geometry>
        <box size="2 1 0.5" />
      </geometry>
      <material name="Orange" />
    </visual>

    <inertial>
      <origin xyz="0 0 0" rpy="0 0 0" />
      <mass value="1" />
      <inertia ixx="0.126164" ixy="0.0" ixz="0.0" iyy="0.416519" iyz="0.0" izz="0.481014" />
    </inertial>
  </link>

  <joint name="chassis_joint" type="fixed">
    <origin xyz="0.8 0 0.5" rpy="0 0 0" />
    <parent link="base_link" />
    <child link="chassis" />
  </joint>

  <!-- left wheel Link -->
  <link name="left_wheel">
    <collision>
      <geometry>
        <cylinder length="0.08" radius="0.3" />
      </geometry>
    </collision>
    <visual>
      <geometry>
        <cylinder length="0.08" radius="0.3" />
      </geometry>
      <material name="Black" />
    </visual>

    <inertial>
      <mass value="2" />
      <inertia ixx="0.145833" ixy="0.0" ixz="0.0" iyy="0.145833" iyz="0.0" izz="0.125" />
    </inertial>
  </link>

  <joint name="left_wheel_joint" type="continuous">
    <origin xyz="-0.8 0.5 -0.2" rpy="-1.57 0 0" />
    <parent link="chassis" />
    <child link="left_wheel" />
    <axis xyz="0 0 1" />
    <dynamics damping="0.2" />
  </joint>

  <!-- right wheel Link -->
  <link name="right_wheel">
    <collision>
      <geometry>
        <cylinder length="0.08" radius="0.3" />
      </geometry>
    </collision>
    <visual>
      <geometry>
        <cylinder length="0.08" radius="0.3" />
      </geometry>
      <material name="Black" />
    </visual>

    <inertial>
      <mass value="2" />
      <inertia ixx="0.145833" ixy="0.0" ixz="0.0" iyy="0.145833" iyz="0.0" izz="0.125" />
    </inertial>
  </link>

  <joint name="right_wheel_joint" type="continuous">
    <origin xyz="-0.8 -0.5 -0.2" rpy="-1.57 0 0" />
    <parent link="chassis" />
    <child link="right_wheel" />
    <axis xyz="0 0 1" />
    <dynamics damping="0.2" />
  </joint>

  <!-- Steering Link -->
  <link name="steering_link">
    <visual>
      <geometry>
        <box size="0.01 0.01 0.01" />
      </geometry>
      <material name="Black" />
    </visual>
    <inertial>
      <origin xyz="0 0 0" rpy="0 0 0" />
      <mass value="0.005" />
      <inertia ixx="0.1" ixy="0.0" ixz="0.0" iyy="0.1" iyz="0.0" izz="0.1" />
    </inertial>
  </link>

  <joint name="steering_joint" type="continuous">
    <origin xyz="0.9 0 -0.2" rpy="0 0 0" />
    <parent link="chassis" />
    <child link="steering_link" />
    <axis xyz="0 0 1" />
  </joint>

  <!-- traction wheel link -->
    <joint name="traction_joint" type="continuous">
    <parent link="steering_link" />
    <child link="wheel_front_link" />
    <origin xyz="0 0 0" rpy="-1.57 1.57 0" />
    <axis xyz="0 0 1" />
  </joint>
  
  <link name="wheel_front_link">
    <visual>
      <geometry>
        <cylinder length="0.08" radius="0.3" />
      </geometry>
      <material name="Black" />
    </visual>
    <inertial>
      <origin xyz="0 0 0" rpy="0 0 0" />
      <mass value="15" />
      <inertia ixx="1" ixy="0" ixz="0" iyy="1" iyz="0" izz="1" />
    </inertial>
    <collision>
      <geometry>
        <cylinder length="0.08" radius="0.3" />
      </geometry>
    </collision>
  </link>



  <!-- imu -->
  <link name="imu_link">
    <visual>
      <geometry>
        <box size="0.1 0.1 0.1"/>
      </geometry>
    </visual>

    <collision>
      <geometry>
        <box size="0.1 0.1 0.1"/>
      </geometry>
    </collision>
  </link>

  <joint name="imu_joint" type="fixed">
    <parent link="chassis"/>
    <child link="imu_link"/>
    <origin xyz="0 0 0.01"/>
  </joint>

  <gazebo reference="imu_link">
    <sensor name="imu_sensor" type="imu">
    <plugin filename="libgazebo_ros_imu_sensor.so" name="imu_plugin">
        <ros>
          <namespace>/demo</namespace>
          <remapping>~/out:=imu</remapping>
        </ros>
        <initial_orientation_as_reference>false</initial_orientation_as_reference>
      </plugin>
      <always_on>true</always_on>
      <update_rate>100</update_rate>
      <visualize>true</visualize>
      <imu>
        <angular_velocity>
          <x>
            <noise type="gaussian">
              <mean>0.0</mean>
              <stddev>2e-4</stddev>
              <bias_mean>0.0000075</bias_mean>
              <bias_stddev>0.0000008</bias_stddev>
            </noise>
          </x>
          <y>
            <noise type="gaussian">
              <mean>0.0</mean>
              <stddev>2e-4</stddev>
              <bias_mean>0.0000075</bias_mean>
              <bias_stddev>0.0000008</bias_stddev>
            </noise>
          </y>
          <z>
            <noise type="gaussian">
              <mean>0.0</mean>
              <stddev>2e-4</stddev>
              <bias_mean>0.0000075</bias_mean>
              <bias_stddev>0.0000008</bias_stddev>
            </noise>
          </z>
        </angular_velocity>
        <linear_acceleration>
          <x>
            <noise type="gaussian">
              <mean>0.0</mean>
              <stddev>1.7e-2</stddev>
              <bias_mean>0.1</bias_mean>
              <bias_stddev>0.001</bias_stddev>
            </noise>
          </x>
          <y>
            <noise type="gaussian">
              <mean>0.0</mean>
              <stddev>1.7e-2</stddev>
              <bias_mean>0.1</bias_mean>
              <bias_stddev>0.001</bias_stddev>
            </noise>
          </y>
          <z>
            <noise type="gaussian">
              <mean>0.0</mean>
              <stddev>1.7e-2</stddev>
              <bias_mean>0.1</bias_mean>
              <bias_stddev>0.001</bias_stddev>
            </noise>
          </z>
        </linear_acceleration>
      </imu>
    </sensor>
  </gazebo> 

  <!-- lidar  -->
  <link name="lidar_link">
  <inertial>
    <origin xyz="0 0 0" rpy="0 0 0"/>
    <mass value="0.125"/>
    <inertia ixx="0.001"  ixy="0"  ixz="0" iyy="0.001" iyz="0" izz="0.001" />
  </inertial>

  <collision>
    <origin xyz="0 0 0" rpy="0 0 0"/>
    <geometry>
       <cylinder radius="0.0508" length="0.055"/>
    </geometry>
  </collision>

  <visual>
    <origin xyz="0 0 0" rpy="0 0 0"/>
    <geometry>
       <cylinder radius="0.0508" length="0.055"/>
    </geometry>
  </visual>
</link>

<joint name="lidar_joint" type="fixed">
  <parent link="chassis"/>
  <child link="lidar_link"/>
  <origin xyz="0 0 0.27" rpy="0 0 0"/>
</joint>

<gazebo reference="lidar_link">
  <sensor name="lidar" type="ray">
    <always_on>true</always_on>
    <visualize>true</visualize>
    <update_rate>5</update_rate>
    <ray>
      <scan>
        <horizontal>
          <samples>360</samples>
          <resolution>1.000000</resolution>
          <min_angle>0.000000</min_angle>
          <max_angle>6.280000</max_angle>
        </horizontal>
      </scan>
      <range>
        <min>0.120000</min>
        <max>3.5</max>
        <resolution>0.015000</resolution>
      </range>
      <noise>
        <type>gaussian</type>
        <mean>0.0</mean>
        <stddev>0.01</stddev>
      </noise>
    </ray>
    <plugin name="scan" filename="libgazebo_ros_ray_sensor.so">
      <ros>
        <remapping>~/out:=scan</remapping>
      </ros>
      <output_type>sensor_msgs/LaserScan</output_type>
      <frame_name>lidar_link</frame_name>
    </plugin>
  </sensor>
</gazebo>

  <!-- ros2 control -->
  <ros2_control name="GazeboSystem" type="system">
    <hardware>
      <plugin>gazebo_ros2_control/GazeboSystem</plugin>
    </hardware>
    <joint name="steering_joint">
      <command_interface name="position" />
      <state_interface name="position" />
    </joint>
    <joint name="left_wheel_joint">
      <command_interface name="velocity" />
      <state_interface name="velocity" />
      <state_interface name="position" />
    </joint>
    <joint name="right_wheel_joint">
      <command_interface name="velocity" />
      <state_interface name="velocity" />
      <state_interface name="position" />
    </joint>
  </ros2_control>

  <gazebo>
    <plugin filename="libgazebo_ros2_control.so" name="gazebo_ros2_control">
      <parameters>$(find tricycle_sim)/config/tricycle_steering_controller.yaml</parameters>
    </plugin>
  </gazebo>

</robot>
